Workbook
Name 菜品资料: 'Item Master'!$B$4:$D$119

Sheet Item Master
A2: Procurement information cross-reference table
A3: 序号 | B3: 菜品（马来语） | C3: 菜品（中文） | D3: 商品类别 | E3: 单位 | F3: =IFERROR(SUMIF('1.1'!C:C, C3, '1.1'!E:E), 0)+IFERROR(SUMIF('1.2'!C:C, C3, '1.2'!E:E), 0)+IFERROR(SUMIF('1.3'!C:C, C3, '1.3'!E:E), 0)+IFERROR(SUMIF('1.4'!C:C, C3, '1.4'!E:E), 0)+IFERROR(SUMIF('1.5'!C:C, C3, '1.5'!E:E), 0)+IFERROR(SUMIF('1.6'!C:C, C3, '1.6'!E:E), 0)+IFERROR(SUMIF('1.7'!C:C, C3, '1.7'!E:E), 0)+IFERROR(SUMIF('1.8'!C:C, C3, '1.8'!E:E), 0)+IFERROR(SUMIF('1.9'!C:C, C3, '1.9'!E:E), 0)+IFERROR(SUMIF('1.10'!C:C, C3, '1.10'!E:E), 0)+IFERROR(SUMIF('1.11'!C:C, C3, '1.11'!E:E), 0)+IFERROR(SUMIF('1.12'!C:C, C3, '1.12'!E:E), 0)+IFERROR(SUMIF('1.13'!C:C, C3, '1.13'!E:E), 0)+IFERROR(SUMIF('1.14'!C:C, C3, '1.14'!E:E), 0)+IFERROR(SUMIF('1.15'!C:C, C3, '1.15'!E:E), 0)+IFERROR(SUMIF('1.16'!C:C, C3, '1.16'!E:E), 0)+IFERROR(SUMIF('1.17'!C:C, C3, '1.17'!E:E), 0)+IFERROR(SUMIF('1.18'!C:C, C3, '1.18'!E:E), 0)+IFERROR(SUMIF('1.19'!C:C, C3, '1.19'!E:E), 0)+IFERROR(SUMIF('1.20'!C:C, C3, '1.20'!E:E), 0)+IFERROR(SUMIF('1.21'!C:C, C3, '1.21'!E:E), 0)+IFERROR(SUMIF('1.22'!C:C, C3, '1.22'!E:E), 0)+IFERROR(SUMIF('1.23'!C:C, C3, '1.23'!E:E), 0)+IFERROR(SUMIF('1.24'!C:C, C3, '1.24'!E:E), 0)+IFERROR(SUMIF('1.25'!C:C, C3, '1.25'!E:E), 0)+IFERROR(SUMIF('1.26'!C:C, C3, '1.26'!E:E), 0)+IFERROR(SUMIF('1.27'!C:C, C3, '1.27'!E:E), 0)+IFERROR(SUMIF('1.28'!C:C, C3, '1.28'!E:E), 0)+IFERROR(SUMIF('1.29'!C:C, C3, '1.29'!E:E), 0)+IFERROR(SUMIF('1.30'!C:C, C3, '1.30'!E:E), 0)+IFERROR(SUMIF('1.31'!C:C, C3, '1.31'!E:E), 0)+IFERROR(SUMIF('2.1'!C:C, C3, '2.1'!E:E), 0)+IFERROR(SUMIF('2.2'!C:C, C3, '2.2'!E:E), 0)+IFERROR(SUMIF('2.3'!C:C, C3, '2.3'!E:E), 0)+IFERROR(SUMIF('2.4'!C:C, C3, '2.4'!E:E), 0)+IFERROR(SUMIF('2.5'!C:C, C3, '2.5'!E:E), 0)+IFERROR(SUMIF('2.6'!C:C, C3, '2.6'!E:E), 0)+IFERROR(SUMIF('2.7'!C:C, C3, '2.7'!E:E), 0)+IFERROR(SUMIF('2.8'!C:C, C3, '2.8'!E:E), 0)+IFERROR(SUMIF('2.9'!C:C, C3, '2.9'!E:E), 0)+IFERROR(SUMIF('2.10'!C:C, C3, '2.10'!E:E), 0)+IFERROR(SUMIF('2.11'!C:C, C3, '2.11'!E:E), 0)+IFERROR(SUMIF('2.12'!C:C, C3, '2.12'!E:E), 0)+IFERROR(SUMIF('2.13'!C:C, C3, '2.13'!E:E), 0)+IFERROR(SUMIF('2.14'!C:C, C3, '2.14'!E:E), 0)+IFERROR(SUMIF('2.15'!C:C, C3, '2.15'!E:E), 0)+IFERROR(SUMIF('2.16'!C:C, C3, '2.16'!E:E), 0)+IFERROR(SUMIF('2.17'!C:C, C3, '2.17'!E:E), 0)+IFERROR(SUMIF('2.18'!C:C, C3, '2.18'!E:E), 0)+IFERROR(SUMIF('2.19'!C:C, C3, '2.19'!E:E), 0)+IFERROR(SUMIF('2.20'!C:C, C3, '2.20'!E:E), 0)+IFERROR(SUMIF('2.21'!C:C, C3, '2.21'!E:E), 0)+IFERROR(SUMIF('2.22'!C:C, C3, '2.22'!E:E), 0)+IFERROR(SUMIF('2.23'!C:C, C3, '2.23'!E:E), 0)+IFERROR(SUMIF('2.24'!C:C, C3, '2.24'!E:E), 0)+IFERROR(SUMIF('2.25'!C:C, C3, '2.25'!E:E), 0)+IFERROR(SUMIF('2.26'!C:C, C3, '2.26'!E:E), 0)+IFERROR(SUMIF('2.27'!C:C, C3, '2.27'!E:E), 0)+IFERROR(SUMIF('2.28'!C:C, C3, '2.28'!E:E), 0)+IFERROR(SUMIF('3.1'!C:C, C3, '3.1'!E:E), 0)+IFERROR(SUMIF('3.2'!C:C, C3, '3.2'!E:E), 0)+IFERROR(SUMIF('3.3'!C:C, C3, '3.3'!E:E), 0)+IFERROR(SUMIF('3.4'!C:C, C3, '3.4'!E:E), 0)+IFERROR(SUMIF('3.5'!C:C, C3, '3.5'!E:E), 0)+IFERROR(SUMIF('3.6'!C:C, C3, '3.6'!E:E), 0)+IFERROR(SUMIF('3.7'!C:C, C3, '3.7'!E:E), 0)+IFERROR(SUMIF('3.8'!C:C, C3, '3.8'!E:E), 0)+IFERROR(SUMIF('3.9'!C:C, C3, '3.9'!E:E), 0)+IFERROR(SUMIF('3.10'!C:C, C3, '3.10'!E:E), 0)+IFERROR(SUMIF('3.11'!C:C, C3, '3.11'!E:E), 0)+IFERROR(SUMIF('3.12'!C:C, C3, '3.12'!E:E), 0)+IFERROR(SUMIF('3.13'!C:C, C3, '3.13'!E:E), 0)+IFERROR(SUMIF('3.14'!C:C, C3, '3.14'!E:E), 0)+IFERROR(SUMIF('3.15'!C:C, C3, '3.15'!E:E), 0)+IFERROR(SUMIF('3.16'!C:C, C3, '3.16'!E:E), 0)+IFERROR(SUMIF('3.17'!C:C, C3, '3.17'!E:E), 0)+IFERROR(SUMIF('3.18'!C:C, C3, '3.18'!E:E), 0)+IFERROR(SUMIF('3.19'!C:C, C3, '3.19'!E:E), 0)+IFERROR(SUMIF('3.20'!C:C, C3, '3.20'!E:E), 0)+IFERROR(SUMIF('3.21'!C:C, C3, '3.21'!E:E), 0)+IFERROR(SUMIF('3.22'!C:C, C3, '3.22'!E:E), 0)+IFERROR(SUMIF('3.23'!C:C, C3, '3.23'!E:E), 0)+IFERROR(SUMIF('3.24'!C:C, C3, '3.24'!E:E), 0)+IFERROR(SUMIF('3.25'!C:C, C3, '3.25'!E:E), 0)+IFERROR(SUMIF('3.26'!C:C, C3, '3.26'!E:E), 0)+IFERROR(SUMIF('3.27'!C:C, C3, '3.27'!E:E), 0)+IFERROR(SUMIF('3.28'!C:C, C3, '3.28'!E:E), 0)+IFERROR(SUMIF('3.29'!C:C, C3, '3.29'!E:E), 0)+IFERROR(SUMIF('3.30'!C:C, C3, '3.30'!E:E), 0)+IFERROR(SUMIF('3.31'!C:C, C3, '3.31'!E:E), 0)+IFERROR(SUMIF('4.1'!C:C, C3, '4.1'!E:E), 0)+IFERROR(SUMIF('4.2'!C:C, C3, '4.2'!E:E), 0)+IFERROR(SUMIF('4.3'!C:C, C3, '4.3'!E:E), 0)+IFERROR(SUMIF('4.4'!C:C, C3, '4.4'!E:E), 0)+IFERROR(SUMIF('4.5'!C:C, C3, '4.5'!E:E), 0)+IFERROR(SUMIF('4.6'!C:C, C3, '4.6'!E:E), 0)+IFERROR(SUMIF('4.7'!C:C, C3, '4.7'!E:E), 0)+IFERROR(SUMIF('4.8'!C:C, C3, '4.8'!E:E), 0)+IFERROR(SUMIF('4.9'!C:C, C3, '4.9'!E:E), 0)+IFERROR(SUMIF('4.10'!C:C, C3, '4.10'!E:E), 0)+IFERROR(SUMIF('4.11'!C:C, C3, '4.11'!E:E), 0)+IFERROR(SUMIF('4.12'!C:C, C3, '4.12'!E:E), 0)+IFERROR(SUMIF('4.13'!C:C, C3, '4.13'!E:E), 0)+IFERROR(SUMIF('4.14'!C:C, C3, '4.14'!E:E), 0)+IFERROR(SUMIF('4.15'!C:C, C3, '4.15'!E:E), 0)+IFERROR(SUMIF('4.16'!C:C, C3, '4.16'!E:E), 0)+IFERROR(SUMIF('4.17'!C:C, C3, '4.17'!E:E), 0)+IFERROR(SUMIF('4.18'!C:C, C3, '4.18'!E:E), 0)+IFERROR(SUMIF('4.19'!C:C, C3, '4.19'!E:E), 0)+IFERROR(SUMIF('4.20'!C:C, C3, '4.20'!E:E), 0)+IFERROR(SUMIF('4.21'!C:C, C3, '4.21'!E:E), 0)+IFERROR(SUMIF('4.22'!C:C, C3, '4.22'!E:E), 0)+IFERROR(SUMIF('4.23'!C:C, C3, '4.23'!E:E), 0)+IFERROR(SUMIF('4.24'!C:C, C3, '4.24'!E:E), 0)+IFERROR(SUMIF('4.25'!C:C, C3, '4.25'!E:E), 0)+IFERROR(SUMIF('4.26'!C:C, C3, '4.26'!E:E), 0)+IFERROR(SUMIF('4.27'!C:C, C3, '4.27'!E:E), 0)+IFERROR(SUMIF('4.28'!C:C, C3, '4.28'!E:E), 0)+IFERROR(SUMIF('4.29'!C:C, C3, '4.29'!E:E), 0)+IFERROR(SUMIF('4.30'!C:C, C3, '4.30'!E:E), 0)+IFERROR(SUMIF('5.1'!C:C, C3, '5.1'!E:E), 0)+IFERROR(SUMIF('5.2'!C:C, C3, '5.2'!E:E), 0)+IFERROR(SUMIF('5.3'!C:C, C3, '5.3'!E:E), 0)+IFERROR(SUMIF('5.4'!C:C, C3, '5.4'!E:E), 0)+IFERROR(SUMIF('5.5'!C:C, C3, '5.5'!E:E), 0)+IFERROR(SUMIF('5.6'!C:C, C3, '5.6'!E:E), 0)+IFERROR(SUMIF('5.7'!C:C, C3, '5.7'!E:E), 0)+IFERROR(SUMIF('5.8'!C:C, C3, '5.8'!E:E), 0)+IFERROR(SUMIF('5.9'!C:C, C3, '5.9'!E:E), 0)+IFERROR(SUMIF('5.10'!C:C, C3, '5.10'!E:E), 0)+IFERROR(SUMIF('5.11'!C:C, C3, '5.11'!E:E), 0)+IFERROR(SUMIF('5.12'!C:C, C3, '5.12'!E:E), 0)+IFERROR(SUMIF('5.13'!C:C, C3, '5.13'!E:E), 0)+IFERROR(SUMIF('5.14'!C:C, C3, '5.14'!E:E), 0)+IFERROR(SUMIF('5.15'!C:C, C3, '5.15'!E:E), 0)+IFERROR(SUMIF('5.16'!C:C, C3, '5.16'!E:E), 0)+IFERROR(SUMIF('5.17'!C:C, C3, '5.17'!E:E), 0)+IFERROR(SUMIF('5.18'!C:C, C3, '5.18'!E:E), 0)+IFERROR(SUMIF('5.19'!C:C, C3, '5.19'!E:E), 0)+IFERROR(SUMIF('5.20'!C:C, C3, '5.20'!E:E), 0)+IFERROR(SUMIF('5.21'!C:C, C3, '5.21'!E:E), 0)+IFERROR(SUMIF('5.22'!C:C, C3, '5.22'!E:E), 0)+IFERROR(SUMIF('5.23'!C:C, C3, '5.23'!E:E), 0)+IFERROR(SUMIF('5.24'!C:C, C3, '5.24'!E:E), 0)+IFERROR(SUMIF('5.25'!C:C, C3, '5.25'!E:E), 0)+IFERROR(SUMIF('5.26'!C:C, C3, '5.26'!E:E), 0)+IFERROR(SUMIF('5.27'!C:C, C3, '5.27'!E:E), 0)+IFERROR(SUMIF('5.28'!C:C, C3, '5.28'!E:E), 0)+IFERROR(SUMIF('5.29'!C:C, C3, '5.29'!E:E), 0)+IFERROR(SUMIF('5.30'!C:C, C3, '5.30'!E:E), 0)+IFERROR(SUMIF('5.31'!C:C, C3, '5.31'!E:E), 0)+IFERROR(SUMIF('6.1'!C:C, C3, '6.1'!E:E), 0)+IFERROR(SUMIF('6.2'!C:C, C3, '6.2'!E:E), 0)+IFERROR(SUMIF('6.3'!C:C, C3, '6.3'!E:E), 0)+IFERROR(SUMIF('6.4'!C:C, C3, '6.4'!E:E), 0)+IFERROR(SUMIF('6.5'!C:C, C3, '6.5'!E:E), 0)+IFERROR(SUMIF('6.6'!C:C, C3, '6.6'!E:E), 0)+IFERROR(SUMIF('6.7'!C:C, C3, '6.7'!E:E), 0)+IFERROR(SUMIF('6.8'!C:C, C3, '6.8'!E:E), 0)+IFERROR(SUMIF('6.9'!C:C, C3, '6.9'!E:E), 0)+IFERROR(SUMIF('6.10'!C:C, C3, '6.10'!E:E), 0)+IFERROR(SUMIF('6.11'!C:C, C3, '6.11'!E:E), 0)+IFERROR(SUMIF('6.12'!C:C, C3, '6.12'!E:E), 0)+IFERROR(SUMIF('6.13'!C:C, C3, '6.13'!E:E), 0)+IFERROR(SUMIF('6.14'!C:C, C3, '6.14'!E:E), 0)+IFERROR(SUMIF('6.15'!C:C, C3, '6.15'!E:E), 0)+IFERROR(SUMIF('6.16'!C:C, C3, '6.16'!E:E), 0)+IFERROR(SUMIF('6.17'!C:C, C3, '6.17'!E:E), 0)+IFERROR(SUMIF('6.18'!C:C, C3, '6.18'!E:E), 0)+IFERROR(SUMIF('6.19'!C:C, C3, '6.19'!E:E), 0)+IFERROR(SUMIF('6.20'!C:C, C3, '6.20'!E:E), 0)+IFERROR(SUMIF('6.21'!C:C, C3, '6.21'!E:E), 0)+IFERROR(SUMIF('6.22'!C:C, C3, '6.22'!E:E), 0)+IFERROR(SUMIF('6.23'!C:C, C3, '6.23'!E:E), 0)+IFERROR(SUMIF('6.24'!C:C, C3, '6.24'!E:E), 0)+IFERROR(SUMIF('6.25'!C:C, C3, '6.25'!E:E), 0)+IFERROR(SUMIF('6.26'!C:C, C3, '6.26'!E:E), 0)+IFERROR(SUMIF('6.27'!C:C, C3, '6.27'!E:E), 0)+IFERROR(SUMIF('6.28'!C:C, C3, '6.28'!E:E), 0)+IFERROR(SUMIF('6.29'!C:C, C3, '6.29'!E:E), 0)+IFERROR(SUMIF('6.30'!C:C, C3, '6.30'!E:E), 0)+IFERROR(SUMIF('7.1'!C:C, C3, '7.1'!E:E), 0)+IFERROR(SUMIF('7.2'!C:C, C3, '7.2'!E:E), 0)+IFERROR(SUMIF('7.3'!C:C, C3, '7.3'!E:E), 0)+IFERROR(SUMIF('7.4'!C:C, C3, '7.4'!E:E), 0)+IFERROR(SUMIF('7.5'!C:C, C3, '7.5'!E:E), 0)+IFERROR(SUMIF('7.6'!C:C, C3, '7.6'!E:E), 0)+IFERROR(SUMIF('7.7'!C:C, C3, '7.7'!E:E), 0)+IFERROR(SUMIF('7.8'!C:C, C3, '7.8'!E:E), 0)+IFERROR(SUMIF('7.9'!C:C, C3, '7.9'!E:E), 0)+IFERROR(SUMIF('7.10'!C:C, C3, '7.10'!E:E), 0)+IFERROR(SUMIF('7.11'!C:C, C3, '7.11'!E:E), 0)+IFERROR(SUMIF('7.12'!C:C, C3, '7.12'!E:E), 0)+IFERROR(SUMIF('7.13'!C:C, C3, '7.13'!E:E), 0)+IFERROR(SUMIF('7.14'!C:C, C3, '7.14'!E:E), 0)+IFERROR(SUMIF('7.15'!C:C, C3, '7.15'!E:E), 0)+IFERROR(SUMIF('7.16'!C:C, C3, '7.16'!E:E), 0)+IFERROR(SUMIF('7.17'!C:C, C3, '7.17'!E:E), 0)+IFERROR(SUMIF('7.18'!C:C, C3, '7.18'!E:E), 0)+IFERROR(SUMIF('7.19'!C:C, C3, '7.19'!E:E), 0)+IFERROR(SUMIF('7.20'!C:C, C3, '7.20'!E:E), 0)+IFERROR(SUMIF('7.21'!C:C, C3, '7.21'!E:E), 0)+IFERROR(SUMIF('7.22'!C:C, C3, '7.22'!E:E), 0)+IFERROR(SUMIF('7.23'!C:C, C3, '7.23'!E:E), 0)+IFERROR(SUMIF('7.24'!C:C, C3, '7.24'!E:E), 0)+IFERROR(SUMIF('7.25'!C:C, C3, '7.25'!E:E), 0)+IFERROR(SUMIF('7.26'!C:C, C3, '7.26'!E:E), 0)+IFERROR(SUMIF('7.27'!C:C, C3, '7.27'!E:E), 0)+IFERROR(SUMIF('7.28'!C:C, C3, '7.28'!E:E), 0)+IFERROR(SUMIF('7.29'!C:C, C3, '7.29'!E:E), 0)+IFERROR(SUMIF('7.30'!C:C, C3, '7.30'!E:E), 0)+IFERROR(SUMIF('7.31'!C:C, C3, '7.31'!E:E), 0)+IFERROR(SUMIF('8.1'!C:C, C3, '8.1'!E:E), 0)+IFERROR(SUMIF('8.2'!C:C, C3, '8.2'!E:E), 0)+IFERROR(SUMIF('8.3'!C:C, C3, '8.3'!E:E), 0)+IFERROR(SUMIF('8.4'!C:C, C3, '8.4'!E:E), 0)+IFERROR(SUMIF('8.5'!C:C, C3, '8.5'!E:E), 0)+IFERROR(SUMIF('8.6'!C:C, C3, '8.6'!E:E), 0)+IFERROR(SUMIF('8.7'!C:C, C3, '8.7'!E:E), 0)+IFERROR(SUMIF('8.8'!C:C, C3, '8.8'!E:E), 0)+IFERROR(SUMIF('8.9'!C:C, C3, '8.9'!E:E), 0)+IFERROR(SUMIF('8.10'!C:C, C3, '8.10'!E:E), 0)+IFERROR(SUMIF('8.11'!C:C, C3, '8.11'!E:E), 0)+IFERROR(SUMIF('8.12'!C:C, C3, '8.12'!E:E), 0)+IFERROR(SUMIF('8.13'!C:C, C3, '8.13'!E:E), 0)+IFERROR(SUMIF('8.14'!C:C, C3, '8.14'!E:E), 0)+IFERROR(SUMIF('8.15'!C:C, C3, '8.15'!E:E), 0)+IFERROR(SUMIF('8.16'!C:C, C3, '8.16'!E:E), 0)+IFERROR(SUMIF('8.17'!C:C, C3, '8.17'!E:E), 0)+IFERROR(SUMIF('8.18'!C:C, C3, '8.18'!E:E), 0)+IFERROR(SUMIF('8.19'!C:C, C3, '8.19'!E:E), 0)+IFERROR(SUMIF('8.20'!C:C, C3, '8.20'!E:E), 0)+IFERROR(SUMIF('8.21'!C:C, C3, '8.21'!E:E), 0)+IFERROR(SUMIF('8.22'!C:C, C3, '8.22'!E:E), 0)+IFERROR(SUMIF('8.23'!C:C, C3, '8.23'!E:E), 0)+IFERROR(SUMIF('8.24'!C:C, C3, '8.24'!E:E), 0)+IFERROR(SUMIF('8.25'!C:C, C3, '8.25'!E:E), 0)+IFERROR(SUMIF('8.26'!C:C, C3, '8.26'!E:E), 0)+IFERROR(SUMIF('8.27'!C:C, C3, '8.27'!E:E), 0)+IFERROR(SUMIF('8.28'!C:C, C3, '8.28'!E:E), 0)+IFERROR(SUMIF('8.29'!C:C, C3, '8.29'!E:E), 0)+IFERROR(SUMIF('8.30'!C:C, C3, '8.30'!E:E), 0)+IFERROR(SUMIF('8.31'!C:C, C3, '8.31'!E:E), 0)+IFERROR(SUMIF('9.1'!C:C, C3, '9.1'!E:E), 0)+IFERROR(SUMIF('9.2'!C:C, C3, '9.2'!E:E), 0)+IFERROR(SUMIF('9.3'!C:C, C3, '9.3'!E:E), 0)+IFERROR(SUMIF('9.4'!C:C, C3, '9.4'!E:E), 0)+IFERROR(SUMIF('9.5'!C:C, C3, '9.5'!E:E), 0)+IFERROR(SUMIF('9.6'!C:C, C3, '9.6'!E:E), 0)+IFERROR(SUMIF('9.7'!C:C, C3, '9.7'!E:E), 0)+IFERROR(SUMIF('9.8'!C:C, C3, '9.8'!E:E), 0)+IFERROR(SUMIF('9.9'!C:C, C3, '9.9'!E:E), 0)+IFERROR(SUMIF('9.10'!C:C, C3, '9.10'!E:E), 0)+IFERROR(SUMIF('9.11'!C:C, C3, '9.11'!E:E), 0)+IFERROR(SUMIF('9.12'!C:C, C3, '9.12'!E:E), 0)+IFERROR(SUMIF('9.13'!C:C, C3, '9.13'!E:E), 0)+IFERROR(SUMIF('9.14'!C:C, C3, '9.14'!E:E), 0)+IFERROR(SUMIF('9.15'!C:C, C3, '9.15'!E:E), 0)+IFERROR(SUMIF('9.16'!C:C, C3, '9.16'!E:E), 0)+IFERROR(SUMIF('9.17'!C:C, C3, '9.17'!E:E), 0)+IFERROR(SUMIF('9.18'!C:C, C3, '9.18'!E:E), 0)+IFERROR(SUMIF('9.19'!C:C, C3, '9.19'!E:E), 0)+IFERROR(SUMIF('9.20'!C:C, C3, '9.20'!E:E), 0)+IFERROR(SUMIF('9.21'!C:C, C3, '9.21'!E:E), 0)+IFERROR(SUMIF('9.22'!C:C, C3, '9.22'!E:E), 0)+IFERROR(SUMIF('9.23'!C:C, C3, '9.23'!E:E), 0)+IFERROR(SUMIF('9.24'!C:C, C3, '9.24'!E:E), 0)+IFERROR(SUMIF('9.25'!C:C, C3, '9.25'!E:E), 0)+IFERROR(SUMIF('9.26'!C:C, C3, '9.26'!E:E), 0)+IFERROR(SUMIF('9.27'!C:C, C3, '9.27'!E:E), 0)+IFERROR(SUMIF('9.28'!C:C, C3, '9.28'!E:E), 0)+IFERROR(SUMIF('9.29'!C:C, C3, '9.29'!E:E), 0)+IFERROR(SUMIF('9.30'!C:C, C3, '9.30'!E:E), 0)+IFERROR(SUMIF('10.1'!C:C, C3, '10.1'!E:E), 0)+IFERROR(SUMIF('10.2'!C:C, C3, '10.2'!E:E), 0)+IFERROR(SUMIF('10.3'!C:C, C3, '10.3'!E:E), 0)+IFERROR(SUMIF('10.4'!C:C, C3, '10.4'!E:E), 0)+IFERROR(SUMIF('10.5'!C:C, C3, '10.5'!E:E), 0)+IFERROR(SUMIF('10.6'!C:C, C3, '10.6'!E:E), 0)+IFERROR(SUMIF('10.7'!C:C, C3, '10.7'!E:E), 0)+IFERROR(SUMIF('10.8'!C:C, C3, '10.8'!E:E), 0)+IFERROR(SUMIF('10.9'!C:C, C3, '10.9'!E:E), 0)+IFERROR(SUMIF('10.10'!C:C, C3, '10.10'!E:E), 0)+IFERROR(SUMIF('10.11'!C:C, C3, '10.11'!E:E), 0)+IFERROR(SUMIF('10.12'!C:C, C3, '10.12'!E:E), 0)+IFERROR(SUMIF('10.13'!C:C, C3, '10.13'!E:E), 0)+IFERROR(SUMIF('10.14'!C:C, C3, '10.14'!E:E), 0)+IFERROR(SUMIF('10.15'!C:C, C3, '10.15'!E:E), 0)+IFERROR(SUMIF('10.16'!C:C, C3, '10.16'!E:E), 0)+IFERROR(SUMIF('10.17'!C:C, C3, '10.17'!E:E), 0)+IFERROR(SUMIF('10.18'!C:C, C3, '10.18'!E:E), 0)+IFERROR(SUMIF('10.19'!C:C, C3, '10.19'!E:E), 0)+IFERROR(SUMIF('10.20'!C:C, C3, '10.20'!E:E), 0)+IFERROR(SUMIF('10.21'!C:C, C3, '10.21'!E:E), 0)+IFERROR(SUMIF('10.22'!C:C, C3, '10.22'!E:E), 0)+IFERROR(SUMIF('10.23'!C:C, C3, '10.23'!E:E), 0)+IFERROR(SUMIF('10.24'!C:C, C3, '10.24'!E:E), 0)+IFERROR(SUMIF('10.25'!C:C, C3, '10.25'!E:E), 0)+IFERROR(SUMIF('10.26'!C:C, C3, '10.26'!E:E), 0)+IFERROR(SUMIF('10.27'!C:C, C3, '10.27'!E:E), 0)+IFERROR(SUMIF('10.28'!C:C, C3, '10.28'!E:E), 0)+IFERROR(SUMIF('10.29'!C:C, C3, '10.29'!E:E), 0)+IFERROR(SUMIF('10.30'!C:C, C3, '10.30'!E:E), 0)+IFERROR(SUMIF('10.31'!C:C, C3, '10.31'!E:E), 0)+IFERROR(SUMIF('11.1'!C:C, C3, '11.1'!E:E), 0)+IFERROR(SUMIF('11.2'!C:C, C3, '11.2'!E:E), 0)+IFERROR(SUMIF('11.3'!C:C, C3, '11.3'!E:E), 0)+IFERROR(SUMIF('11.4'!C:C, C3, '11.4'!E:E), 0)+IFERROR(SUMIF('11.5'!C:C, C3, '11.5'!E:E), 0)+IFERROR(SUMIF('11.6'!C:C, C3, '11.6'!E:E), 0)+IFERROR(SUMIF('11.7'!C:C, C3, '11.7'!E:E), 0)+IFERROR(SUMIF('11.8'!C:C, C3, '11.8'!E:E), 0)+IFERROR(SUMIF('11.9'!C:C, C3, '11.9'!E:E), 0)+IFERROR(SUMIF('11.10'!C:C, C3, '11.10'!E:E), 0)+IFERROR(SUMIF('11.11'!C:C, C3, '11.11'!E:E), 0)+IFERROR(SUMIF('11.12'!C:C, C3, '11.12'!E:E), 0)+IFERROR(SUMIF('11.13'!C:C, C3, '11.13'!E:E), 0)+IFERROR(SUMIF('11.14'!C:C, C3, '11.14'!E:E), 0)+IFERROR(SUMIF('11.15'!C:C, C3, '11.15'!E:E), 0)+IFERROR(SUMIF('11.16'!C:C, C3, '11.16'!E:E), 0)+IFERROR(SUMIF('11.17'!C:C, C3, '11.17'!E:E), 0)+IFERROR(SUMIF('11.18'!C:C, C3, '11.18'!E:E), 0)+IFERROR(SUMIF('11.19'!C:C, C3, '11.19'!E:E), 0)+IFERROR(SUMIF('11.20'!C:C, C3, '11.20'!E:E), 0)+IFERROR(SUMIF('11.21'!C:C, C3, '11.21'!E:E), 0)+IFERROR(SUMIF('11.22'!C:C, C3, '11.22'!E:E), 0)+IFERROR(SUMIF('11.23'!C:C, C3, '11.23'!E:E), 0)+IFERROR(SUMIF('11.24'!C:C, C3, '11.24'!E:E), 0)+IFERROR(SUMIF('11.25'!C:C, C3, '11.25'!E:E), 0)+IFERROR(SUMIF('11.26'!C:C, C3, '11.26'!E:E), 0)+IFERROR(SUMIF('11.27'!C:C, C3, '11.27'!E:E), 0)+IFERROR(SUMIF('11.28'!C:C, C3, '11.28'!E:E), 0)+IFERROR(SUMIF('11.29'!C:C, C3, '11.29'!E:E), 0)+IFERROR(SUMIF('11.30'!C:C, C3, '11.30'!E:E), 0)+IFERROR(SUMIF('12.1'!C:C, C3, '12.1'!E:E), 0)+IFERROR(SUMIF('12.2'!C:C, C3, '12.2'!E:E), 0)+IFERROR(SUMIF('12.3'!C:C, C3, '12.3'!E:E), 0)+IFERROR(SUMIF('12.4'!C:C, C3, '12.4'!E:E), 0)+IFERROR(SUMIF('12.5'!C:C, C3, '12.5'!E:E), 0)+IFERROR(SUMIF('12.6'!C:C, C3, '12.6'!E:E), 0)+IFERROR(SUMIF('12.7'!C:C, C3, '12.7'!E:E), 0)+IFERROR(SUMIF('12.8'!C:C, C3, '12.8'!E:E), 0)+IFERROR(SUMIF('12.9'!C:C, C3, '12.9'!E:E), 0)+IFERROR(SUMIF('12.10'!C:C, C3, '12.10'!E:E), 0)+IFERROR(SUMIF('12.11'!C:C, C3, '12.11'!E:E), 0)+IFERROR(SUMIF('12.12'!C:C, C3, '12.12'!E:E), 0)+IFERROR(SUMIF('12.13'!C:C, C3, '12.13'!E:E), 0)+IFERROR(SUMIF('12.14'!C:C, C3, '12.14'!E:E), 0)+IFERROR(SUMIF('12.15'!C:C, C3, '12.15'!E:E), 0)+IFERROR(SUMIF('12.16'!C:C, C3, '12.16'!E:E), 0)+IFERROR(SUMIF('12.17'!C:C, C3, '12.17'!E:E), 0)+IFERROR(SUMIF('12.18'!C:C, C3, '12.18'!E:E), 0)+IFERROR(SUMIF('12.19'!C:C, C3, '12.19'!E:E), 0)+IFERROR(SUMIF('12.20'!C:C, C3, '12.20'!E:E), 0)+IFERROR(SUMIF('12.21'!C:C, C3, '12.21'!E:E), 0)+IFERROR(SUMIF('12.22'!C:C, C3, '12.22'!E:E), 0)+IFERROR(SUMIF('12.23'!C:C, C3, '12.23'!E:E), 0)+IFERROR(SUMIF('12.24'!C:C, C3, '12.24'!E:E), 0)+IFERROR(SUMIF('12.25'!C:C, C3, '12.25'!E:E), 0)+IFERROR(SUMIF('12.26'!C:C, C3, '12.26'!E:E), 0)+IFERROR(SUMIF('12.27'!C:C, C3, '12.27'!E:E), 0)+IFERROR(SUMIF('12.28'!C:C, C3, '12.28'!E:E), 0)+IFERROR(SUMIF('12.29'!C:C, C3, '12.29'!E:E), 0)+IFERROR(SUMIF('12.30'!C:C, C3, '12.30'!E:E), 0)+IFERROR(SUMIF('12.31'!C:C, C3, '12.31'!E:E), 0) -> 0 | G3: =IFERROR(SUMIF('1.1'!C:C, C3, '1.1'!G:G), 0)+IFERROR(SUMIF('1.2'!C:C, C3, '1.2'!G:G), 0)+IFERROR(SUMIF('1.3'!C:C, C3, '1.3'!G:G), 0)+IFERROR(SUMIF('1.4'!C:C, C3, '1.4'!G:G), 0)+IFERROR(SUMIF('1.5'!C:C, C3, '1.5'!G:G), 0)+IFERROR(SUMIF('1.6'!C:C, C3, '1.6'!G:G), 0)+IFERROR(SUMIF('1.7'!C:C, C3, '1.7'!G:G), 0)+IFERROR(SUMIF('1.8'!C:C, C3, '1.8'!G:G), 0)+IFERROR(SUMIF('1.9'!C:C, C3, '1.9'!G:G), 0)+IFERROR(SUMIF('1.10'!C:C, C3, '1.10'!G:G), 0)+IFERROR(SUMIF('1.11'!C:C, C3, '1.11'!G:G), 0)+IFERROR(SUMIF('1.12'!C:C, C3, '1.12'!G:G), 0)+IFERROR(SUMIF('1.13'!C:C, C3, '1.13'!G:G), 0)+IFERROR(SUMIF('1.14'!C:C, C3, '1.14'!G:G), 0)+IFERROR(SUMIF('1.15'!C:C, C3, '1.15'!G:G), 0)+IFERROR(SUMIF('1.16'!C:C, C3, '1.16'!G:G), 0)+IFERROR(SUMIF('1.17'!C:C, C3, '1.17'!G:G), 0)+IFERROR(SUMIF('1.18'!C:C, C3, '1.18'!G:G), 0)+IFERROR(SUMIF('1.19'!C:C, C3, '1.19'!G:G), 0)+IFERROR(SUMIF('1.20'!C:C, C3, '1.20'!G:G), 0)+IFERROR(SUMIF('1.21'!C:C, C3, '1.21'!G:G), 0)+IFERROR(SUMIF('1.22'!C:C, C3, '1.22'!G:G), 0)+IFERROR(SUMIF('1.23'!C:C, C3, '1.23'!G:G), 0)+IFERROR(SUMIF('1.24'!C:C, C3, '1.24'!G:G), 0)+IFERROR(SUMIF('1.25'!C:C, C3, '1.25'!G:G), 0)+IFERROR(SUMIF('1.26'!C:C, C3, '1.26'!G:G), 0)+IFERROR(SUMIF('1.27'!C:C, C3, '1.27'!G:G), 0)+IFERROR(SUMIF('1.28'!C:C, C3, '1.28'!G:G), 0)+IFERROR(SUMIF('1.29'!C:C, C3, '1.29'!G:G), 0)+IFERROR(SUMIF('1.30'!C:C, C3, '1.30'!G:G), 0)+IFERROR(SUMIF('1.31'!C:C, C3, '1.31'!G:G), 0)+IFERROR(SUMIF('2.1'!C:C, C3, '2.1'!G:G), 0)+IFERROR(SUMIF('2.2'!C:C, C3, '2.2'!G:G), 0)+IFERROR(SUMIF('2.3'!C:C, C3, '2.3'!G:G), 0)+IFERROR(SUMIF('2.4'!C:C, C3, '2.4'!G:G), 0)+IFERROR(SUMIF('2.5'!C:C, C3, '2.5'!G:G), 0)+IFERROR(SUMIF('2.6'!C:C, C3, '2.6'!G:G), 0)+IFERROR(SUMIF('2.7'!C:C, C3, '2.7'!G:G), 0)+IFERROR(SUMIF('2.8'!C:C, C3, '2.8'!G:G), 0)+IFERROR(SUMIF('2.9'!C:C, C3, '2.9'!G:G), 0)+IFERROR(SUMIF('2.10'!C:C, C3, '2.10'!G:G), 0)+IFERROR(SUMIF('2.11'!C:C, C3, '2.11'!G:G), 0)+IFERROR(SUMIF('2.12'!C:C, C3, '2.12'!G:G), 0)+IFERROR(SUMIF('2.13'!C:C, C3, '2.13'!G:G), 0)+IFERROR(SUMIF('2.14'!C:C, C3, '2.14'!G:G), 0)+IFERROR(SUMIF('2.15'!C:C, C3, '2.15'!G:G), 0)+IFERROR(SUMIF('2.16'!C:C, C3, '2.16'!G:G), 0)+IFERROR(SUMIF('2.17'!C:C, C3, '2.17'!G:G), 0)+IFERROR(SUMIF('2.18'!C:C, C3, '2.18'!G:G), 0)+IFERROR(SUMIF('2.19'!C:C, C3, '2.19'!G:G), 0)+IFERROR(SUMIF('2.20'!C:C, C3, '2.20'!G:G), 0)+IFERROR(SUMIF('2.21'!C:C, C3, '2.21'!G:G), 0)+IFERROR(SUMIF('2.22'!C:C, C3, '2.22'!G:G), 0)+IFERROR(SUMIF('2.23'!C:C, C3, '2.23'!G:G), 0)+IFERROR(SUMIF('2.24'!C:C, C3, '2.24'!G:G), 0)+IFERROR(SUMIF('2.25'!C:C, C3, '2.25'!G:G), 0)+IFERROR(SUMIF('2.26'!C:C, C3, '2.26'!G:G), 0)+IFERROR(SUMIF('2.27'!C:C, C3, '2.27'!G:G), 0)+IFERROR(SUMIF('2.28'!C:C, C3, '2.28'!G:G), 0)+IFERROR(SUMIF('3.1'!C:C, C3, '3.1'!G:G), 0)+IFERROR(SUMIF('3.2'!C:C, C3, '3.2'!G:G), 0)+IFERROR(SUMIF('3.3'!C:C, C3, '3.3'!G:G), 0)+IFERROR(SUMIF('3.4'!C:C, C3, '3.4'!G:G), 0)+IFERROR(SUMIF('3.5'!C:C, C3, '3.5'!G:G), 0)+IFERROR(SUMIF('3.6'!C:C, C3, '3.6'!G:G), 0)+IFERROR(SUMIF('3.7'!C:C, C3, '3.7'!G:G), 0)+IFERROR(SUMIF('3.8'!C:C, C3, '3.8'!G:G), 0)+IFERROR(SUMIF('3.9'!C:C, C3, '3.9'!G:G), 0)+IFERROR(SUMIF('3.10'!C:C, C3, '3.10'!G:G), 0)+IFERROR(SUMIF('3.11'!C:C, C3, '3.11'!G:G), 0)+IFERROR(SUMIF('3.12'!C:C, C3, '3.12'!G:G), 0)+IFERROR(SUMIF('3.13'!C:C, C3, '3.13'!G:G), 0)+IFERROR(SUMIF('3.14'!C:C, C3, '3.14'!G:G), 0)+IFERROR(SUMIF('3.15'!C:C, C3, '3.15'!G:G), 0)+IFERROR(SUMIF('3.16'!C:C, C3, '3.16'!G:G), 0)+IFERROR(SUMIF('3.17'!C:C, C3, '3.17'!G:G), 0)+IFERROR(SUMIF('3.18'!C:C, C3, '3.18'!G:G), 0)+IFERROR(SUMIF('3.19'!C:C, C3, '3.19'!G:G), 0)+IFERROR(SUMIF('3.20'!C:C, C3, '3.20'!G:G), 0)+IFERROR(SUMIF('3.21'!C:C, C3, '3.21'!G:G), 0)+IFERROR(SUMIF('3.22'!C:C, C3, '3.22'!G:G), 0)+IFERROR(SUMIF('3.23'!C:C, C3, '3.23'!G:G), 0)+IFERROR(SUMIF('3.24'!C:C, C3, '3.24'!G:G), 0)+IFERROR(SUMIF('3.25'!C:C, C3, '3.25'!G:G), 0)+IFERROR(SUMIF('3.26'!C:C, C3, '3.26'!G:G), 0)+IFERROR(SUMIF('3.27'!C:C, C3, '3.27'!G:G), 0)+IFERROR(SUMIF('3.28'!C:C, C3, '3.28'!G:G), 0)+IFERROR(SUMIF('3.29'!C:C, C3, '3.29'!G:G), 0)+IFERROR(SUMIF('3.30'!C:C, C3, '3.30'!G:G), 0)+IFERROR(SUMIF('3.31'!C:C, C3, '3.31'!G:G), 0)+IFERROR(SUMIF('4.1'!C:C, C3, '4.1'!G:G), 0)+IFERROR(SUMIF('4.2'!C:C, C3, '4.2'!G:G), 0)+IFERROR(SUMIF('4.3'!C:C, C3, '4.3'!G:G), 0)+IFERROR(SUMIF('4.4'!C:C, C3, '4.4'!G:G), 0)+IFERROR(SUMIF('4.5'!C:C, C3, '4.5'!G:G), 0)+IFERROR(SUMIF('4.6'!C:C, C3, '4.6'!G:G), 0)+IFERROR(SUMIF('4.7'!C:C, C3, '4.7'!G:G), 0)+IFERROR(SUMIF('4.8'!C:C, C3, '4.8'!G:G), 0)+IFERROR(SUMIF('4.9'!C:C, C3, '4.9'!G:G), 0)+IFERROR(SUMIF('4.10'!C:C, C3, '4.10'!G:G), 0)+IFERROR(SUMIF('4.11'!C:C, C3, '4.11'!G:G), 0)+IFERROR(SUMIF('4.12'!C:C, C3, '4.12'!G:G), 0)+IFERROR(SUMIF('4.13'!C:C, C3, '4.13'!G:G), 0)+IFERROR(SUMIF('4.14'!C:C, C3, '4.14'!G:G), 0)+IFERROR(SUMIF('4.15'!C:C, C3, '4.15'!G:G), 0)+IFERROR(SUMIF('4.16'!C:C, C3, '4.16'!G:G), 0)+IFERROR(SUMIF('4.17'!C:C, C3, '4.17'!G:G), 0)+IFERROR(SUMIF('4.18'!C:C, C3, '4.18'!G:G), 0)+IFERROR(SUMIF('4.19'!C:C, C3, '4.19'!G:G), 0)+IFERROR(SUMIF('4.20'!C:C, C3, '4.20'!G:G), 0)+IFERROR(SUMIF('4.21'!C:C, C3, '4.21'!G:G), 0)+IFERROR(SUMIF('4.22'!C:C, C3, '4.22'!G:G), 0)+IFERROR(SUMIF('4.23'!C:C, C3, '4.23'!G:G), 0)+IFERROR(SUMIF('4.24'!C:C, C3, '4.24'!G:G), 0)+IFERROR(SUMIF('4.25'!C:C, C3, '4.25'!G:G), 0)+IFERROR(SUMIF('4.26'!C:C, C3, '4.26'!G:G), 0)+IFERROR(SUMIF('4.27'!C:C, C3, '4.27'!G:G), 0)+IFERROR(SUMIF('4.28'!C:C, C3, '4.28'!G:G), 0)+IFERROR(SUMIF('4.29'!C:C, C3, '4.29'!G:G), 0)+IFERROR(SUMIF('4.30'!C:C, C3, '4.30'!G:G), 0)+IFERROR(SUMIF('5.1'!C:C, C3, '5.1'!G:G), 0)+IFERROR(SUMIF('5.2'!C:C, C3, '5.2'!G:G), 0)+IFERROR(SUMIF('5.3'!C:C, C3, '5.3'!G:G), 0)+IFERROR(SUMIF('5.4'!C:C, C3, '5.4'!G:G), 0)+IFERROR(SUMIF('5.5'!C:C, C3, '5.5'!G:G), 0)+IFERROR(SUMIF('5.6'!C:C, C3, '5.6'!G:G), 0)+IFERROR(SUMIF('5.7'!C:C, C3, '5.7'!G:G), 0)+IFERROR(SUMIF('5.8'!C:C, C3, '5.8'!G:G), 0)+IFERROR(SUMIF('5.9'!C:C, C3, '5.9'!G:G), 0)+IFERROR(SUMIF('5.10'!C:C, C3, '5.10'!G:G), 0)+IFERROR(SUMIF('5.11'!C:C, C3, '5.11'!G:G), 0)+IFERROR(SUMIF('5.12'!C:C, C3, '5.12'!G:G), 0)+IFERROR(SUMIF('5.13'!C:C, C3, '5.13'!G:G), 0)+IFERROR(SUMIF('5.14'!C:C, C3, '5.14'!G:G), 0)+IFERROR(SUMIF('5.15'!C:C, C3, '5.15'!G:G), 0)+IFERROR(SUMIF('5.16'!C:C, C3, '5.16'!G:G), 0)+IFERROR(SUMIF('5.17'!C:C, C3, '5.17'!G:G), 0)+IFERROR(SUMIF('5.18'!C:C, C3, '5.18'!G:G), 0)+IFERROR(SUMIF('5.19'!C:C, C3, '5.19'!G:G), 0)+IFERROR(SUMIF('5.20'!C:C, C3, '5.20'!G:G), 0)+IFERROR(SUMIF('5.21'!C:C, C3, '5.21'!G:G), 0)+IFERROR(SUMIF('5.22'!C:C, C3, '5.22'!G:G), 0)+IFERROR(SUMIF('5.23'!C:C, C3, '5.23'!G:G), 0)+IFERROR(SUMIF('5.24'!C:C, C3, '5.24'!G:G), 0)+IFERROR(SUMIF('5.25'!C:C, C3, '5.25'!G:G), 0)+IFERROR(SUMIF('5.26'!C:C, C3, '5.26'!G:G), 0)+IFERROR(SUMIF('5.27'!C:C, C3, '5.27'!G:G), 0)+IFERROR(SUMIF('5.28'!C:C, C3, '5.28'!G:G), 0)+IFERROR(SUMIF('5.29'!C:C, C3, '5.29'!G:G), 0)+IFERROR(SUMIF('5.30'!C:C, C3, '5.30'!G:G), 0)+IFERROR(SUMIF('5.31'!C:C, C3, '5.31'!G:G), 0)+IFERROR(SUMIF('6.1'!C:C, C3, '6.1'!G:G), 0)+IFERROR(SUMIF('6.2'!C:C, C3, '6.2'!G:G), 0)+IFERROR(SUMIF('6.3'!C:C, C3, '6.3'!G:G), 0)+IFERROR(SUMIF('6.4'!C:C, C3, '6.4'!G:G), 0)+IFERROR(SUMIF('6.5'!C:C, C3, '6.5'!G:G), 0)+IFERROR(SUMIF('6.6'!C:C, C3, '6.6'!G:G), 0)+IFERROR(SUMIF('6.7'!C:C, C3, '6.7'!G:G), 0)+IFERROR(SUMIF('6.8'!C:C, C3, '6.8'!G:G), 0)+IFERROR(SUMIF('6.9'!C:C, C3, '6.9'!G:G), 0)+IFERROR(SUMIF('6.10'!C:C, C3, '6.10'!G:G), 0)+IFERROR(SUMIF('6.11'!C:C, C3, '6.11'!G:G), 0)+IFERROR(SUMIF('6.12'!C:C, C3, '6.12'!G:G), 0)+IFERROR(SUMIF('6.13'!C:C, C3, '6.13'!G:G), 0)+IFERROR(SUMIF('6.14'!C:C, C3, '6.14'!G:G), 0)+IFERROR(SUMIF('6.15'!C:C, C3, '6.15'!G:G), 0)+IFERROR(SUMIF('6.16'!C:C, C3, '6.16'!G:G), 0)+IFERROR(SUMIF('6.17'!C:C, C3, '6.17'!G:G), 0)+IFERROR(SUMIF('6.18'!C:C, C3, '6.18'!G:G), 0)+IFERROR(SUMIF('6.19'!C:C, C3, '6.19'!G:G), 0)+IFERROR(SUMIF('6.20'!C:C, C3, '6.20'!G:G), 0)+IFERROR(SUMIF('6.21'!C:C, C3, '6.21'!G:G), 0)+IFERROR(SUMIF('6.22'!C:C, C3, '6.22'!G:G), 0)+IFERROR(SUMIF('6.23'!C:C, C3, '6.23'!G:G), 0)+IFERROR(SUMIF('6.24'!C:C, C3, '6.24'!G:G), 0)+IFERROR(SUMIF('6.25'!C:C, C3, '6.25'!G:G), 0)+IFERROR(SUMIF('6.26'!C:C, C3, '6.26'!G:G), 0)+IFERROR(SUMIF('6.27'!C:C, C3, '6.27'!G:G), 0)+IFERROR(SUMIF('6.28'!C:C, C3, '6.28'!G:G), 0)+IFERROR(SUMIF('6.29'!C:C, C3, '6.29'!G:G), 0)+IFERROR(SUMIF('6.30'!C:C, C3, '6.30'!G:G), 0)+IFERROR(SUMIF('7.1'!C:C, C3, '7.1'!G:G), 0)+IFERROR(SUMIF('7.2'!C:C, C3, '7.2'!G:G), 0)+IFERROR(SUMIF('7.3'!C:C, C3, '7.3'!G:G), 0)+IFERROR(SUMIF('7.4'!C:C, C3, '7.4'!G:G), 0)+IFERROR(SUMIF('7.5'!C:C, C3, '7.5'!G:G), 0)+IFERROR(SUMIF('7.6'!C:C, C3, '7.6'!G:G), 0)+IFERROR(SUMIF('7.7'!C:C, C3, '7.7'!G:G), 0)+IFERROR(SUMIF('7.8'!C:C, C3, '7.8'!G:G), 0)+IFERROR(SUMIF('7.9'!C:C, C3, '7.9'!G:G), 0)+IFERROR(SUMIF('7.10'!C:C, C3, '7.10'!G:G), 0)+IFERROR(SUMIF('7.11'!C:C, C3, '7.11'!G:G), 0)+IFERROR(SUMIF('7.12'!C:C, C3, '7.12'!G:G), 0)+IFERROR(SUMIF('7.13'!C:C, C3, '7.13'!G:G), 0)+IFERROR(SUMIF('7.14'!C:C, C3, '7.14'!G:G), 0)+IFERROR(SUMIF('7.15'!C:C, C3, '7.15'!G:G), 0)+IFERROR(SUMIF('7.16'!C:C, C3, '7.16'!G:G), 0)+IFERROR(SUMIF('7.17'!C:C, C3, '7.17'!G:G), 0)+IFERROR(SUMIF('7.18'!C:C, C3, '7.18'!G:G), 0)+IFERROR(SUMIF('7.19'!C:C, C3, '7.19'!G:G), 0)+IFERROR(SUMIF('7.20'!C:C, C3, '7.20'!G:G), 0)+IFERROR(SUMIF('7.21'!C:C, C3, '7.21'!G:G), 0)+IFERROR(SUMIF('7.22'!C:C, C3, '7.22'!G:G), 0)+IFERROR(SUMIF('7.23'!C:C, C3, '7.23'!G:G), 0)+IFERROR(SUMIF('7.24'!C:C, C3, '7.24'!G:G), 0)+IFERROR(SUMIF('7.25'!C:C, C3, '7.25'!G:G), 0)+IFERROR(SUMIF('7.26'!C:C, C3, '7.26'!G:G), 0)+IFERROR(SUMIF('7.27'!C:C, C3, '7.27'!G:G), 0)+IFERROR(SUMIF('7.28'!C:C, C3, '7.28'!G:G), 0)+IFERROR(SUMIF('7.29'!C:C, C3, '7.29'!G:G), 0)+IFERROR(SUMIF('7.30'!C:C, C3, '7.30'!G:G), 0)+IFERROR(SUMIF('7.31'!C:C, C3, '7.31'!G:G), 0)+IFERROR(SUMIF('8.1'!C:C, C3, '8.1'!G:G), 0)+IFERROR(SUMIF('8.2'!C:C, C3, '8.2'!G:G), 0)+IFERROR(SUMIF('8.3'!C:C, C3, '8.3'!G:G), 0)+IFERROR(SUMIF('8.4'!C:C, C3, '8.4'!G:G), 0)+IFERROR(SUMIF('8.5'!C:C, C3, '8.5'!G:G), 0)+IFERROR(SUMIF('8.6'!C:C, C3, '8.6'!G:G), 0)+IFERROR(SUMIF('8.7'!C:C, C3, '8.7'!G:G), 0)+IFERROR(SUMIF('8.8'!C:C, C3, '8.8'!G:G), 0)+IFERROR(SUMIF('8.9'!C:C, C3, '8.9'!G:G), 0)+IFERROR(SUMIF('8.10'!C:C, C3, '8.10'!G:G), 0)+IFERROR(SUMIF('8.11'!C:C, C3, '8.11'!G:G), 0)+IFERROR(SUMIF('8.12'!C:C, C3, '8.12'!G:G), 0)+IFERROR(SUMIF('8.13'!C:C, C3, '8.13'!G:G), 0)+IFERROR(SUMIF('8.14'!C:C, C3, '8.14'!G:G), 0)+IFERROR(SUMIF('8.15'!C:C, C3, '8.15'!G:G), 0)+IFERROR(SUMIF('8.16'!C:C, C3, '8.16'!G:G), 0)+IFERROR(SUMIF('8.17'!C:C, C3, '8.17'!G:G), 0)+IFERROR(SUMIF('8.18'!C:C, C3, '8.18'!G:G), 0)+IFERROR(SUMIF('8.19'!C:C, C3, '8.19'!G:G), 0)+IFERROR(SUMIF('8.20'!C:C, C3, '8.20'!G:G), 0)+IFERROR(SUMIF('8.21'!C:C, C3, '8.21'!G:G), 0)+IFERROR(SUMIF('8.22'!C:C, C3, '8.22'!G:G), 0)+IFERROR(SUMIF('8.23'!C:C, C3, '8.23'!G:G), 0)+IFERROR(SUMIF('8.24'!C:C, C3, '8.24'!G:G), 0)+IFERROR(SUMIF('8.25'!C:C, C3, '8.25'!G:G), 0)+IFERROR(SUMIF('8.26'!C:C, C3, '8.26'!G:G), 0)+IFERROR(SUMIF('8.27'!C:C, C3, '8.27'!G:G), 0)+IFERROR(SUMIF('8.28'!C:C, C3, '8.28'!G:G), 0)+IFERROR(SUMIF('8.29'!C:C, C3, '8.29'!G:G), 0)+IFERROR(SUMIF('8.30'!C:C, C3, '8.30'!G:G), 0)+IFERROR(SUMIF('8.31'!C:C, C3, '8.31'!G:G), 0)+IFERROR(SUMIF('9.1'!C:C, C3, '9.1'!G:G), 0)+IFERROR(SUMIF('9.2'!C:C, C3, '9.2'!G:G), 0)+IFERROR(SUMIF('9.3'!C:C, C3, '9.3'!G:G), 0)+IFERROR(SUMIF('9.4'!C:C, C3, '9.4'!G:G), 0)+IFERROR(SUMIF('9.5'!C:C, C3, '9.5'!G:G), 0)+IFERROR(SUMIF('9.6'!C:C, C3, '9.6'!G:G), 0)+IFERROR(SUMIF('9.7'!C:C, C3, '9.7'!G:G), 0)+IFERROR(SUMIF('9.8'!C:C, C3, '9.8'!G:G), 0)+IFERROR(SUMIF('9.9'!C:C, C3, '9.9'!G:G), 0)+IFERROR(SUMIF('9.10'!C:C, C3, '9.10'!G:G), 0)+IFERROR(SUMIF('9.11'!C:C, C3, '9.11'!G:G), 0)+IFERROR(SUMIF('9.12'!C:C, C3, '9.12'!G:G), 0)+IFERROR(SUMIF('9.13'!C:C, C3, '9.13'!G:G), 0)+IFERROR(SUMIF('9.14'!C:C, C3, '9.14'!G:G), 0)+IFERROR(SUMIF('9.15'!C:C, C3, '9.15'!G:G), 0)+IFERROR(SUMIF('9.16'!C:C, C3, '9.16'!G:G), 0)+IFERROR(SUMIF('9.17'!C:C, C3, '9.17'!G:G), 0)+IFERROR(SUMIF('9.18'!C:C, C3, '9.18'!G:G), 0)+IFERROR(SUMIF('9.19'!C:C, C3, '9.19'!G:G), 0)+IFERROR(SUMIF('9.20'!C:C, C3, '9.20'!G:G), 0)+IFERROR(SUMIF('9.21'!C:C, C3, '9.21'!G:G), 0)+IFERROR(SUMIF('9.22'!C:C, C3, '9.22'!G:G), 0)+IFERROR(SUMIF('9.23'!C:C, C3, '9.23'!G:G), 0)+IFERROR(SUMIF('9.24'!C:C, C3, '9.24'!G:G), 0)+IFERROR(SUMIF('9.25'!C:C, C3, '9.25'!G:G), 0)+IFERROR(SUMIF('9.26'!C:C, C3, '9.26'!G:G), 0)+IFERROR(SUMIF('9.27'!C:C, C3, '9.27'!G:G), 0)+IFERROR(SUMIF('9.28'!C:C, C3, '9.28'!G:G), 0)+IFERROR(SUMIF('9.29'!C:C, C3, '9.29'!G:G), 0)+IFERROR(SUMIF('9.30'!C:C, C3, '9.30'!G:G), 0)+IFERROR(SUMIF('10.1'!C:C, C3, '10.1'!G:G), 0)+IFERROR(SUMIF('10.2'!C:C, C3, '10.2'!G:G), 0)+IFERROR(SUMIF('10.3'!C:C, C3, '10.3'!G:G), 0)+IFERROR(SUMIF('10.4'!C:C, C3, '10.4'!G:G), 0)+IFERROR(SUMIF('10.5'!C:C, C3, '10.5'!G:G), 0)+IFERROR(SUMIF('10.6'!C:C, C3, '10.6'!G:G), 0)+IFERROR(SUMIF('10.7'!C:C, C3, '10.7'!G:G), 0)+IFERROR(SUMIF('10.8'!C:C, C3, '10.8'!G:G), 0)+IFERROR(SUMIF('10.9'!C:C, C3, '10.9'!G:G), 0)+IFERROR(SUMIF('10.10'!C:C, C3, '10.10'!G:G), 0)+IFERROR(SUMIF('10.11'!C:C, C3, '10.11'!G:G), 0)+IFERROR(SUMIF('10.12'!C:C, C3, '10.12'!G:G), 0)+IFERROR(SUMIF('10.13'!C:C, C3, '10.13'!G:G), 0)+IFERROR(SUMIF('10.14'!C:C, C3, '10.14'!G:G), 0)+IFERROR(SUMIF('10.15'!C:C, C3, '10.15'!G:G), 0)+IFERROR(SUMIF('10.16'!C:C, C3, '10.16'!G:G), 0)+IFERROR(SUMIF('10.17'!C:C, C3, '10.17'!G:G), 0)+IFERROR(SUMIF('10.18'!C:C, C3, '10.18'!G:G), 0)+IFERROR(SUMIF('10.19'!C:C, C3, '10.19'!G:G), 0)+IFERROR(SUMIF('10.20'!C:C, C3, '10.20'!G:G), 0)+IFERROR(SUMIF('10.21'!C:C, C3, '10.21'!G:G), 0)+IFERROR(SUMIF('10.22'!C:C, C3, '10.22'!G:G), 0)+IFERROR(SUMIF('10.23'!C:C, C3, '10.23'!G:G), 0)+IFERROR(SUMIF('10.24'!C:C, C3, '10.24'!G:G), 0)+IFERROR(SUMIF('10.25'!C:C, C3, '10.25'!G:G), 0)+IFERROR(SUMIF('10.26'!C:C, C3, '10.26'!G:G), 0)+IFERROR(SUMIF('10.27'!C:C, C3, '10.27'!G:G), 0)+IFERROR(SUMIF('10.28'!C:C, C3, '10.28'!G:G), 0)+IFERROR(SUMIF('10.29'!C:C, C3, '10.29'!G:G), 0)+IFERROR(SUMIF('10.30'!C:C, C3, '10.30'!G:G), 0)+IFERROR(SUMIF('10.31'!C:C, C3, '10.31'!G:G), 0)+IFERROR(SUMIF('11.1'!C:C, C3, '11.1'!G:G), 0)+IFERROR(SUMIF('11.2'!C:C, C3, '11.2'!G:G), 0)+IFERROR(SUMIF('11.3'!C:C, C3, '11.3'!G:G), 0)+IFERROR(SUMIF('11.4'!C:C, C3, '11.4'!G:G), 0)+IFERROR(SUMIF('11.5'!C:C, C3, '11.5'!G:G), 0)+IFERROR(SUMIF('11.6'!C:C, C3, '11.6'!G:G), 0)+IFERROR(SUMIF('11.7'!C:C, C3, '11.7'!G:G), 0)+IFERROR(SUMIF('11.8'!C:C, C3, '11.8'!G:G), 0)+IFERROR(SUMIF('11.9'!C:C, C3, '11.9'!G:G), 0)+IFERROR(SUMIF('11.10'!C:C, C3, '11.10'!G:G), 0)+IFERROR(SUMIF('11.11'!C:C, C3, '11.11'!G:G), 0)+IFERROR(SUMIF('11.12'!C:C, C3, '11.12'!G:G), 0)+IFERROR(SUMIF('11.13'!C:C, C3, '11.13'!G:G), 0)+IFERROR(SUMIF('11.14'!C:C, C3, '11.14'!G:G), 0)+IFERROR(SUMIF('11.15'!C:C, C3, '11.15'!G:G), 0)+IFERROR(SUMIF('11.16'!C:C, C3, '11.16'!G:G), 0)+IFERROR(SUMIF('11.17'!C:C, C3, '11.17'!G:G), 0)+IFERROR(SUMIF('11.18'!C:C, C3, '11.18'!G:G), 0)+IFERROR(SUMIF('11.19'!C:C, C3, '11.19'!G:G), 0)+IFERROR(SUMIF('11.20'!C:C, C3, '11.20'!G:G), 0)+IFERROR(SUMIF('11.21'!C:C, C3, '11.21'!G:G), 0)+IFERROR(SUMIF('11.22'!C:C, C3, '11.22'!G:G), 0)+IFERROR(SUMIF('11.23'!C:C, C3, '11.23'!G:G), 0)+IFERROR(SUMIF('11.24'!C:C, C3, '11.24'!G:G), 0)+IFERROR(SUMIF('11.25'!C:C, C3, '11.25'!G:G), 0)+IFERROR(SUMIF('11.26'!C:C, C3, '11.26'!G:G), 0)+IFERROR(SUMIF('11.27'!C:C, C3, '11.27'!G:G), 0)+IFERROR(SUMIF('11.28'!C:C, C3, '11.28'!G:G), 0)+IFERROR(SUMIF('11.29'!C:C, C3, '11.29'!G:G), 0)+IFERROR(SUMIF('11.30'!C:C, C3, '11.30'!G:G), 0)+IFERROR(SUMIF('12.1'!C:C, C3, '12.1'!G:G), 0)+IFERROR(SUMIF('12.2'!C:C, C3, '12.2'!G:G), 0)+IFERROR(SUMIF('12.3'!C:C, C3, '12.3'!G:G), 0)+IFERROR(SUMIF('12.4'!C:C, C3, '12.4'!G:G), 0)+IFERROR(SUMIF('12.5'!C:C, C3, '12.5'!G:G), 0)+IFERROR(SUMIF('12.6'!C:C, C3, '12.6'!G:G), 0)+IFERROR(SUMIF('12.7'!C:C, C3, '12.7'!G:G), 0)+IFERROR(SUMIF('12.8'!C:C, C3, '12.8'!G:G), 0)+IFERROR(SUMIF('12.9'!C:C, C3, '12.9'!G:G), 0)+IFERROR(SUMIF('12.10'!C:C, C3, '12.10'!G:G), 0)+IFERROR(SUMIF('12.11'!C:C, C3, '12.11'!G:G), 0)+IFERROR(SUMIF('12.12'!C:C, C3, '12.12'!G:G), 0)+IFERROR(SUMIF('12.13'!C:C, C3, '12.13'!G:G), 0)+IFERROR(SUMIF('12.14'!C:C, C3, '12.14'!G:G), 0)+IFERROR(SUMIF('12.15'!C:C, C3, '12.15'!G:G), 0)+IFERROR(SUMIF('12.16'!C:C, C3, '12.16'!G:G), 0)+IFERROR(SUMIF('12.17'!C:C, C3, '12.17'!G:G), 0)+IFERROR(SUMIF('12.18'!C:C, C3, '12.18'!G:G), 0)+IFERROR(SUMIF('12.19'!C:C, C3, '12.19'!G:G), 0)+IFERROR(SUMIF('12.20'!C:C, C3, '12.20'!G:G), 0)+IFERROR(SUMIF('12.21'!C:C, C3, '12.21'!G:G), 0)+IFERROR(SUMIF('12.22'!C:C, C3, '12.22'!G:G), 0)+IFERROR(SUMIF('12.23'!C:C, C3, '12.23'!G:G), 0)+IFERROR(SUMIF('12.24'!C:C, C3, '12.24'!G:G), 0)+IFERROR(SUMIF('12.25'!C:C, C3, '12.25'!G:G), 0)+IFERROR(SUMIF('12.26'!C:C, C3, '12.26'!G:G), 0)+IFERROR(SUMIF('12.27'!C:C, C3, '12.27'!G:G), 0)+IFERROR(SUMIF('12.28'!C:C, C3, '12.28'!G:G), 0)+IFERROR(SUMIF('12.29'!C:C, C3, '12.29'!G:G), 0)+IFERROR(SUMIF('12.30'!C:C, C3, '12.30'!G:G), 0)+IFERROR(SUMIF('12.31'!C:C, C3, '12.31'!G:G), 0) -> 0 | H3: 供应商
